const code1 = `let done = true

const isItDoneYet = new Promise((resolve, reject) => {
  if (done) {
    const workDone = 'Here is the thing I built'
    resolve(workDone)
  } else {
    const why = 'Still working on something else'
    reject(why)
  }
})

const checkIfItsDone = () => {
  isItDoneYet
    .then(ok => {
      console.log(ok)
    })
    .catch(err => {
      console.error(err)
    })
}

checkIfItsDone()`
const code2 = `let done = true

const isItDoneYet = new Promise((resolve, reject) => {
  if (done) {
    const workDone = 'Here is the thing I built'
    resolve(workDone)
  } else {
    const why = 'Still working on something else'
    reject(why)
  }
})`

const code3 = `const fs = require('fs')

const getFile = (fileName) => {
  return new Promise((resolve, reject) => {
    fs.readFile(fileName, (err, data) => {
      if (err) {
        reject (err)  // calling \`reject\` will cause the promise to fail with or without the error passed as an argument
        return        // and we don't want to go any further
      }
      resolve(data)
    })
  })
}

getFile('/etc/passwd')
.then(data => console.log(data))
.catch(err => console.error(err))`

const code4 = `const isItDoneYet = new Promise(/* ... as above ... */)
//...

const checkIfItsDone = () => {
  isItDoneYet
    .then(ok => {
      console.log(ok)
    })
    .catch(err => {
      console.error(err)
    })
}`

const code5 = `const status = response => {
  if (response.status >= 200 && response.status < 300) {
    return Promise.resolve(response)
  }
  return Promise.reject(new Error(response.statusText))
}

const json = response => response.json()

fetch('/todos.json')
  .then(status)    // note that the \`status\` function is actually **called** here, and that it **returns a promise***
  .then(json)      // likewise, the only difference here is that the \`json\` function here returns a promise that resolves with \`data\`
  .then(data => {  // ... which is why \`data\` shows up here as the first parameter to the anonymous function
    console.log('Request succeeded with JSON response', data)
  })
  .catch(error => {
    console.log('Request failed', error)
  })`

const code6 = `.then((data) => {
  console.log('Request succeeded with JSON response', data)
})`

const code7 = `new Promise((resolve, reject) => {
  throw new Error('Error')
}).catch(err => {
  console.error(err)
})

// or

new Promise((resolve, reject) => {
  reject('Error')
}).catch(err => {
  console.error(err)
})`

const code8 = `new Promise((resolve, reject) => {
  throw new Error('Error')
})
  .catch(err => {
    throw new Error('Error')
  })
  .catch(err => {
    console.error(err)
  })`

const code9 = `const f1 = fetch('/something.json')
const f2 = fetch('/something2.json')

Promise.all([f1, f2])
  .then(res => {
    console.log('Array of results', res)
  })
  .catch(err => {
    console.error(err)
  })`

const code10 = `Promise.all([f1, f2]).then(([res1, res2]) => {
  console.log('Results', res1, res2)
})`

const code11 = `const first = new Promise((resolve, reject) => {
  setTimeout(resolve, 500, 'first')
})
const second = new Promise((resolve, reject) => {
  setTimeout(resolve, 100, 'second')
})

Promise.race([first, second]).then(result => {
  console.log(result) // second
})`
export default{
  code1,
  code2,
  code3,
  code4,
  code5,
  code6,
  code7,
  code8,
  code9,
  code10,
  code11
}